<?xml version='1.0' ?>
<robot name='urdf_tutorial'>
  <material name='black'>
    <color rgba='0.0 0.0 0.0 1.0'/>
  </material>
  <material name='orange'>
    <color rgba='1.0 0.4 0.0 1.0'/>
  </material>

  <!-- 기저 -->
  <link name='base'/>
  <joint name='fixed' type='fixed'>
    <!-- 일반적으로 기저에 가까운 link가 parent이다 -->
    <parent link='base'/>
    <child link='link1'/>
  </joint>

  <!-- 로봇 팔이 향할 방향을 설정하는 링크 -->
  <link name='link1'>
    <collision>
      <origin xyz='0 0 0.25' rpy='0 0 0'/>
      <geometry>
        <!-- Z축의 경우 origin을 기준으로 -0.25, +0.25 -->
        <box size='0.1 0.1 0.5'/>
      </geometry>
    </collision>
    <visual>
      <origin xyz='0 0 0.25' rpy='0 0 0'/>
      <geometry>
        <box size='0.1 0.1 0.5'/>
        <!-- STL, DAE 등의 매쉬 파일을 사용하여 표현 가능 -->
        <!-- <mesh filename='package://open_manipulator_description/meshes/chain_link1.stl' scale='0.001 0.001 0.001'/> -->
      </geometry>
      <material name='black'/>
    </visual>
    <inertial>
      <origin xyz='0 0 0.25' rpy='0 0 0'/>
      <mass value='1'/>
      <inertia ixx='1.0' ixy='1.0' ixz='0.0' iyy='1.0' iyz='0.0' izz='1.0'/>
    </inertial>
  </link>

  <joint name='joint1' type='revolute'>
    <parent link='link1'/>
    <child link='link2'/>
    <origin xyz='0 0 0.5' rpy='0 0 0'/>
    <!-- 로봇 팔이 z축을 기준으로 회전한다 -->
    <axis xyz='0 0 1'/>
    <limit effort='30' lower='-2.617' upper='2.617' velocity='1.571'/>
  </joint>

  <link name='link2'>
    <collision>
      <origin xyz='0 0 0.25' rpy='0 0 0'/>
      <geometry>
        <box size='0.1 0.1 0.5'/>
      </geometry>
    </collision>
    <visual>
      <origin xyz='0 0 0.25' rpy='0 0 0'/>
      <geometry>
        <box size='0.1 0.1 0.5'/>
      </geometry>
      <material name='orange'/>
    </visual>
    <inertial>
      <origin xyz='0 0 0.25' rpy='0 0 0'/>
      <mass value='1'/>
      <inertia ixx='1.0' ixy='0.0' ixz='0.0' iyy='1.0' iyz='0.0' izz='1.0'/>
    </inertial>
  </link>

  <joint name='joint2' type='revolute'>
    <parent link='link2'/>
    <child link='link3'/>
    <origin xyz='0 0 0.5' rpy='0 0 0'/>
    <axis xyz='0 1 0'/>
    <limit effort='30' lower='-2.617' upper='2.617' velocity='1.571'/>
  </joint>

  <link name='link3'>
    <collision>
      <origin xyz='0 0 0.5' rpy='0 0 0'/>
      <geometry>
        <box size='0.1 0.1 1'/>
      </geometry>
    </collision>
    <visual>
      <origin xyz='0 0 0.5' rpy='0 0 0'/>
      <geometry>
        <box size='0.1 0.1 1'/>
      </geometry>
      <material name='black'/>
    </visual>
    <inertial>
      <origin xyz='0 0 0.5' rpy='0 0 0'/>
      <mass value='1'/>
      <inertia ixx='1.0' ixy='0.0' ixz='0.0' iyy='1.0' iyz='0.0' izz='1.0'/>
    </inertial>
  </link>

  <joint name='joint3' type='revolute'>
    <parent link='link3'/>
    <child link='link4'/>
    <origin xyz='0 0 1' rpy='0 0 0'/>
    <axis xyz='0 1 0'/>
    <limit effort='30' lower='-2.617' upper='2.617' velocity='1.571'/>
  </joint>

  <link name='link4'>
    <collision>
      <origin xyz='0 0 0.25' rpy='0 0 0'/>
      <geometry>
        <box size='0.1 0.1 0.5'/>
      </geometry>
    </collision>
    <visual>
      <origin xyz='0 0 0.25' rpy='0 0 0'/>
      <geometry>
        <box size='0.1 0.1 0.5'/>
      </geometry>
      <material name='orange'/>
    </visual>
    <inertial>
      <origin xyz='0 0 0.25' rpy='0 0 0'/>
      <mass value='1'/>
      <inertia ixx='1.0' ixy='0.0' ixz='0.0' iyy='1.0' iyz='0.0' izz='1.0'/>
    </inertial>
  </link>
</robot>
